Workbook

Sheet Overview
B2: Partner Discussion Worksheet
B3: Goodcare Dental Booking Platform — May 2026
B5: Welcome
B6: This workbook is for you and your business partner to walk through together. It contains everything we still need to decide before going live with paying customers, plus a fully editable financial model. Yellow-highlighted cells are editable inputs — change them and the projections update everywhere.
B8: Sheets in this workbook
B9: 1. Overview | C9: This page. Instructions and table of contents.
B10: 2. Checklist | C10: Every topic you need to settle with your partner — business formation, roles, equity, legal, ops. ~60 items.
B11: 3. Cost Inputs | C11: All cost line items as editable cells. Software subscriptions, device costs, scaling tools.
B12: 4. Tier Pricing | C12: Tier prices, mix percentages, weighted-average revenue per clinic. Editable.
B13: 5. Projection | C13: 36-month financial model. Plug in clinic acquisitions per month → see revenue, costs, profit, cash balance.
B14: 6. Profit Split | C14: Partner share scenarios driven by the projection. Adjust splits to model take-home per partner.
B16: How to use this workbook
B17: 1. Read through the Checklist together; tick what you've already agreed.
B18: 2. On Cost Inputs, adjust any cost line that doesn't match your current contracts.
B19: 3. On Tier Pricing, agree on tier prices and the expected customer mix.
B20: 4. On Projection, plug in realistic new-clinic counts per month for the next 12-36 months.
B21: 5. On Profit Split, adjust each partner's share to model take-home.
B22: 6. Re-read Checklist and circle items that block go-live.
B24: Yellow cells = editable inputs
B25: Throughout this workbook, any cell with a warm yellow background is an editable input. Change those — formulas everywhere else recalculate automatically. White cells are calculated; do not type into them.

Sheet Checklist
B2: Checklist — what you and your partner must settle
B3: Tick (insert ✓ in column B) as you agree on each item. Use column D for notes, decisions, or who's responsible. Everything here should be settled before signing your first paid contract.
B5: A · Business formation
B6: ✓ | C6: Item | D6: Notes / Owner / Decision
B7: ☐ | C7: Entity type — Sole Prop, Partnership, LLP, or Sdn Bhd? | D7: Sdn Bhd recommended for liability separation and tax flexibility | F7: Kanan Digital Sdn Bhd
B8: ☐ | C8: SSM business registration | D8: RM 1,500 once. Required before invoicing.
B9: ☐ | C9: Business name reservation | D9: Brand name + .com.my domain availability check
B10: ☐ | C10: Memorandum and Articles of Association | D10: For Sdn Bhd. Engage company secretary.
B11: ☐ | C11: Shareholders agreement (separate from M&A) | D11: Covers what M&A doesn't — vesting, drag-along, etc.
B12: ☐ | C12: Company secretary appointment | D12: RM ~1,200/year. Required for Sdn Bhd.
B13: ☐ | C13: Company bank account (joint or single signatory?) | D13: CIMB, Maybank, Public Bank all offer SME accounts
B14: ☐ | C14: Initial capital injection — how much, from whom? | D14: Recommend RM 10,000–20,000 starting capital
B15: ☐ | C15: Capital structure — ordinary vs preference shares | D15: Default: all ordinary for 2-person founder team
B16: ☐ | C16: Tax filing arrangement (LHDN) | D16: Engage an accountant; ~RM 200–500/month
B18: B · Roles & responsibilities
B19: ✓ | C19: Item | D19: Notes / Owner / Decision
B20: ☐ | C20: Who handles product and engineering? | D20: Currently you. Will it stay that way at clinic #20?
B21: ☐ | C21: Who handles sales and customer pitching? | D21: Field-time intensive. Decide who fields the calls.
B22: ☐ | C22: Who handles customer support and onboarding? | D22: Initially shared; will need ownership at clinic #10
B23: ☐ | C23: Who handles operations (devices, deliveries, training)? | D23: Especially relevant given hardware bundle
B24: ☐ | C24: Who handles legal, compliance, and finance? | D24: DPA, ToS, PDPA, insurance renewals, LHDN
B25: ☐ | C25: Time commitment per partner (full-time vs part-time)? | D25: Affects equity logic
B26: ☐ | C26: Salary payable, or pure equity until profitable? | D26: Most founders go pure equity until profit allows draws
B27: ☐ | C27: Decision-making process — who has final say on what? | D27: Product, pricing, hiring, big spends each need an owner
B28: ☐ | C28: Weekly working rhythm (sync calls, shared dashboards)? | D28: Suggest weekly 1-hour partner sync
B30: C · Equity & profit sharing
B31: ✓ | C31: Item | D31: Notes / Owner / Decision
B32: ☐ | C32: Equity split percentage between partners | D32: 50/50 is simplest. Skewed splits should be justified by contribution.
B33: ☐ | C33: Vesting schedule (cliff + linear)? | D33: Standard: 1-year cliff, 4-year vest. Protects against early exit.
B34: ☐ | C34: Dilution policy if future investors / employees join | D34: ESOP pool typically 10–15%
B35: ☐ | C35: Voting rights (per-share, or special control?) | D35: 1 share = 1 vote standard
B36: ☐ | C36: Drag-along and tag-along rights | D36: Useful if either party may want to sell stake
B37: ☐ | C37: Profit distribution frequency (monthly, quarterly, annual)? | D37: Monthly works for small founder team; quarterly for tax
B38: ☐ | C38: Profit distribution policy (% retained vs paid out)? | D38: Recommend retain 30–50% for growth
B39: ☐ | C39: Reserve fund policy (months of runway to keep on hand) | D39: 6 months of fixed costs minimum
B40: ☐ | C40: Buyout / shotgun clause if partnership fails | D40: Pre-agree the formula
B41: ☐ | C41: Death / disability provisions | D41: Insurance policy or company-paid buyout
B43: D · Pricing & product strategy
B44: ✓ | C44: Item | D44: Notes / Owner / Decision
B45: ☐ | C45: Final pricing tiers — Basic / Standard / Pro / Franchise? | D45: See Tier Pricing sheet for current numbers
...

Sheet Cost Inputs
B2: Cost Inputs — edit yellow cells
B3: These are the costs WE pay. Yellow cells are editable. Other sheets pull from these — change a number here and the projection updates everywhere.
B5: A · Core fixed costs (paid once live)
B6: Item | C6: RM / month | D6: Notes
B7: Claude Code subscription | C7: 400 | D7: Developer tooling. Required for maintenance + new features. | E7: 100 usd per month
B8: Vercel Pro (team plan) | C8: 95 | D8: Required for commercial use. Hosts all clinic instances.
B9: Supabase Pro (1st project) | C9: 120 | D9: Database + auth. PITR backups, 30-day retention.
B10: Domain (.com, amortised RM 50/year) | C10: 4 | D10: Primary domain for subdomains
B11: Google Workspace (business email) | C11: 33 | D11: name@yourbrand.com for credibility
B12: Legal & insurance amortised (one-time RM 5k + RM 1.5–3k/yr) | C12: 250 | D12: Includes DPA + ToS + PI insurance
B13: Fixed monthly subtotal | C13: =SUM(C7:C12) -> 902 | D13: Sum of A. Once a paying clinic goes live, this is your minimum.
B15: B · Scaling tools (added at clinic-count milestones)
B16: Item | C16: RM / month | D16: When to add
B17: Sentry (error tracking) | C17: 120 | D17: Add when clinic count >= 10
B18: Customer support tool (Freshdesk / Intercom) | C18: 350 | D18: Add when clinic count >= 20
B19: Product analytics (PostHog / Mixpanel) | C19: 250 | D19: Add when clinic count >= 30
B20: Freelance dev support (~10 hrs/month) | C20: 1000 | D20: Add when clinic count >= 20
B21: Email service (Resend / SendGrid) | C21: 95 | D21: Add when email reminders launch
B22: Marketing budget (Google Ads, FB Ads) | C22: 1000 | D22: Add when actively scaling
B24: C · Per-clinic variable costs
B25: Item | C25: RM / clinic / mo | D25: Notes
B26: Supabase per clinic (single-tenant, before refactor) | C26: 120 | D26: Each clinic owns its own Supabase project. Multiplied by clinic count BELOW refactor threshold.
B27: Supabase incremental per clinic (multi-tenant, after refactor) | C27: 10 | D27: Shared DB. Per-clinic resource consumption.
B28: Multi-tenant refactor — clinic count when triggered | C28: 4 | D28: At this clinic count, switch from single-tenant per-clinic Supabase cost to multi-tenant incremental.
B30: D · Hardware (optional bundle)
B31: Item | C31: RM | D31: Notes
B32: Basic device (Android tablet) — total cost incl. accessories | C32: 1300 | D32: Lenovo Tab M10 or similar
B33: Standard device (iPad 10.9") — total cost incl. accessories | C33: 2500 | D33: Recommended default
B34: Premium device (iPad Pro 11") — total cost incl. accessories | C34: 4800 | D34: For Pro / Franchise upsell
B35: Device contract length (months) | C35: 36 | D35: Standard 3-year hardware lease
B36: Device insurance (RM / month / device) | C36: 30 | D36: Damage, theft, accidental drops
B37: Replacement reserve (RM / month / device) | C37: 18 | D37: ~8% of device cost annually
B38: Delivery + setup logistics (RM / month / device amortised) | C38: 2 | D38: First-year delivery + on-site install
B40: Standard device — effective monthly cost (amortised + insurance + reserve) | C40: =ROUND('Cost Inputs'!$C$33/'Cost Inputs'!$C$35+'Cost Inputs'!$C$36+'Cost Inputs'!$C$37+'Cost Inputs'!$C$38,0) -> 119 | D40: Used in Projection for hardware-bundled scenarios.
B42: E · Setup fees and one-offs
B43: Item | C43: RM | D43: Notes
B44: Setup fee — software-only / modular | C44: 1500 | D44: Training + onboarding + customisation (no device)
B45: Setup fee — bundled with device | C45: 2500 | D45: Setup + device delivery + on-site install

Sheet Tier Pricing
B2: Tier Pricing — edit yellow cells
B3: Set the price per tier and the expected mix of customers. Weighted-average revenue per clinic is calculated below and feeds the projection.
B5: A · Software tiers (monthly price)
B6: Tier | C6: Monthly (RM) | D6: Mix % | E6: Weighted RM | F6: Notes
B7: Basic | E7: =C7*D7 -> 0 | F7: DoctorPartner sidekick — booking, WhatsApp, attendance, mobile.
B8: Standard | C8: 150 | D8: 0.5 | E8: =C8*D8 -> 75 | F8: Adds duty cal, leave/shift requests, audit, working hours, branding.
B9: Pro | C9: 250 | D9: 0.2 | E9: =C9*D9 -> 50 | F9: Adds revenue analytics, light payroll, locum, certifications expiry.
B10: Franchise | C10: 400 | D10: 0 | E10: =C10*D10 -> 0 | F10: Per-branch pricing. Cross-branch dashboard, royalty tracking, transfers.
B11: Mix total | D11: =SUM(D7:D10) -> 0.7 | F11: Should equal 100%. If not, the projection will normalise.
B12: Weighted avg software revenue per clinic (RM / month) | E12: =SUMPRODUCT(C7:C10,D7:D10)/MAX(SUM(D7:D10),0.0001) -> 178.57143
B14: B · Customer mix across pricing options
B15: Option | C15: Description | D15: % of clinics | E15: Per clinic adj (RM/mo) | F15: Notes
B16: Option A · Bundled | C16: All-in monthly fee | D16: 0.15 | E16: 25 | F16: Premium on top of software. Includes device.
B17: Option C · Modular | C17: Software + separate hardware lease | D17: 0.4 | E17: 0 | F17: Hardware billed at effective monthly cost.
B18: Option B · Setup-loaded | C18: Big setup fee, lower monthly | D18: 0.05 | E18: 0 | F18: Same monthly as software-only; large upfront.
B19: Option D · Software-only | C19: No hardware | D19: 0.4 | E19: 0 | F19: Pure SaaS. No multi-year contract.
B20: Mix total | D20: =SUM(D16:D19) -> 1 | F20: Should equal 100%.
B22: Hardware-attached % | D22: ='Tier Pricing'!$D$16+'Tier Pricing'!$D$17+'Tier Pricing'!$D$18 -> 0.6 | F22: Share of clinics that have a hardware lease.
B23: Weighted avg total revenue per clinic / month (RM) | E23: ='Tier Pricing'!$E$12+'Tier Pricing'!$D$22*'Cost Inputs'!$C$40+'Tier Pricing'!$D$16*'Tier Pricing'!$E$16 -> 253.72143 | F23: Software avg + hardware (if attached) + premium (Option A only).
C28: Standard | E28: Premium
C32: - Patient booking system | E32: -
C33: - Duty calendar + related features

Sheet Projection
B2: 36-Month Financial Projection
B3: Enter your projected new clinic acquisitions in column C (yellow). Everything else calculates. Negative cumulative cash means subsidising from savings; positive means profitable cumulative.
B6: Month | C6: New clinics | D6: Total clinics | E6: Setup fees (RM) | F6: Subscription (RM) | G6: Revenue total (RM) | H6: Fixed cost (RM) | I6: Variable cost (RM) | J6: Cost total (RM) | K6: Net profit (RM) | L6: Cum. cash (RM)
B7: 1 | C7: 1 | D7: =C7 -> 1 | E7: =C7*'Cost Inputs'!$C$44 -> 1500 | F7: =D7*'Tier Pricing'!$E$23 -> 253.72143 | G7: =E7+F7 -> 1753.7214 | H7: ='Cost Inputs'!$C$13+IF(D7>=10,'Cost Inputs'!$C$17,0)+IF(D7>=20,'Cost Inputs'!$C$18,0)+IF(D7>=30,'Cost Inputs'!$C$19,0)+IF(D7>=20,'Cost Inputs'!$C$20,0)+0+0 -> 902 | I7: =IF(D7<='Cost Inputs'!$C$28,D7*'Cost Inputs'!$C$26,D7*'Cost Inputs'!$C$27)+D7*'Tier Pricing'!$D$22*'Cost Inputs'!$C$40 -> 191.4 | J7: =H7+I7 -> 1093.4 | K7: =G7-J7 -> 660.32143 | L7: =K7 -> 660.32143
B8: 2 | C8: 0 | D8: =D7+C8 -> 1 | E8: =C8*'Cost Inputs'!$C$44 -> 0 | F8: =D8*'Tier Pricing'!$E$23 -> 253.72143 | G8: =E8+F8 -> 253.72143 | H8: ='Cost Inputs'!$C$13+IF(D8>=10,'Cost Inputs'!$C$17,0)+IF(D8>=20,'Cost Inputs'!$C$18,0)+IF(D8>=30,'Cost Inputs'!$C$19,0)+IF(D8>=20,'Cost Inputs'!$C$20,0)+0+0 -> 902 | I8: =IF(D8<='Cost Inputs'!$C$28,D8*'Cost Inputs'!$C$26,D8*'Cost Inputs'!$C$27)+D8*'Tier Pricing'!$D$22*'Cost Inputs'!$C$40 -> 191.4 | J8: =H8+I8 -> 1093.4 | K8: =G8-J8 -> -839.67857 | L8: =L7+K8 -> -179.35714
B9: 3 | C9: 0 | D9: =D8+C9 -> 1 | E9: =C9*'Cost Inputs'!$C$44 -> 0 | F9: =D9*'Tier Pricing'!$E$23 -> 253.72143 | G9: =E9+F9 -> 253.72143 | H9: ='Cost Inputs'!$C$13+IF(D9>=10,'Cost Inputs'!$C$17,0)+IF(D9>=20,'Cost Inputs'!$C$18,0)+IF(D9>=30,'Cost Inputs'!$C$19,0)+IF(D9>=20,'Cost Inputs'!$C$20,0)+0+0 -> 902 | I9: =IF(D9<='Cost Inputs'!$C$28,D9*'Cost Inputs'!$C$26,D9*'Cost Inputs'!$C$27)+D9*'Tier Pricing'!$D$22*'Cost Inputs'!$C$40 -> 191.4 | J9: =H9+I9 -> 1093.4 | K9: =G9-J9 -> -839.67857 | L9: =L8+K9 -> -1019.0357
B10: 4 | C10: 1 | D10: =D9+C10 -> 2 | E10: =C10*'Cost Inputs'!$C$44 -> 1500 | F10: =D10*'Tier Pricing'!$E$23 -> 507.44286 | G10: =E10+F10 -> 2007.4429 | H10: ='Cost Inputs'!$C$13+IF(D10>=10,'Cost Inputs'!$C$17,0)+IF(D10>=20,'Cost Inputs'!$C$18,0)+IF(D10>=30,'Cost Inputs'!$C$19,0)+IF(D10>=20,'Cost Inputs'!$C$20,0)+0+0 -> 902 | I10: =IF(D10<='Cost Inputs'!$C$28,D10*'Cost Inputs'!$C$26,D10*'Cost Inputs'!$C$27)+D10*'Tier Pricing'!$D$22*'Cost Inputs'!$C$40 -> 382.8 | J10: =H10+I10 -> 1284.8 | K10: =G10-J10 -> 722.64286 | L10: =L9+K10 -> -296.39286
B11: 5 | C11: 1 | D11: =D10+C11 -> 3 | E11: =C11*'Cost Inputs'!$C$44 -> 1500 | F11: =D11*'Tier Pricing'!$E$23 -> 761.16429 | G11: =E11+F11 -> 2261.1643 | H11: ='Cost Inputs'!$C$13+IF(D11>=10,'Cost Inputs'!$C$17,0)+IF(D11>=20,'Cost Inputs'!$C$18,0)+IF(D11>=30,'Cost Inputs'!$C$19,0)+IF(D11>=20,'Cost Inputs'!$C$20,0)+0+0 -> 902 | I11: =IF(D11<='Cost Inputs'!$C$28,D11*'Cost Inputs'!$C$26,D11*'Cost Inputs'!$C$27)+D11*'Tier Pricing'!$D$22*'Cost Inputs'!$C$40 -> 574.2 | J11: =H11+I11 -> 1476.2 | K11: =G11-J11 -> 784.96429 | L11: =L10+K11 -> 488.57143
B12: 6 | C12: 0 | D12: =D11+C12 -> 3 | E12: =C12*'Cost Inputs'!$C$44 -> 0 | F12: =D12*'Tier Pricing'!$E$23 -> 761.16429 | G12: =E12+F12 -> 761.16429 | H12: ='Cost Inputs'!$C$13+IF(D12>=10,'Cost Inputs'!$C$17,0)+IF(D12>=20,'Cost Inputs'!$C$18,0)+IF(D12>=30,'Cost Inputs'!$C$19,0)+IF(D12>=20,'Cost Inputs'!$C$20,0)+0+0 -> 902 | I12: =IF(D12<='Cost Inputs'!$C$28,D12*'Cost Inputs'!$C$26,D12*'Cost Inputs'!$C$27)+D12*'Tier Pricing'!$D$22*'Cost Inputs'!$C$40 -> 574.2 | J12: =H12+I12 -> 1476.2 | K12: =G12-J12 -> -715.03571 | L12: =L11+K12 -> -226.46429
B13: 7 | C13: 1 | D13: =D12+C13 -> 4 | E13: =C13*'Cost Inputs'!$C$44 -> 1500 | F13: =D13*'Tier Pricing'!$E$23 -> 1014.8857 | G13: =E13+F13 -> 2514.8857 | H13: ='Cost Inputs'!$C$13+IF(D13>=10,'Cost Inputs'!$C$17,0)+IF(D13>=20,'Cost Inputs'!$C$18,0)+IF(D13>=30,'Cost Inputs'!$C$19,0)+IF(D13>=20,'Cost Inputs'!$C$20,0)+0+0 -> 902 | I13: =IF(D13<='Cost Inputs'!$C$28,D13*'Cost Inputs'!$C$26,D13*'Cost Inputs'!$C$27)+D13*'Tier Pricing'!$D$22*'Cost Inputs'!$C$40 -> 765.6 | J13: =H13+I13 -> 1667.6 | K13: =G13-J13 -> 847.28571 | L13: =L12+K13 -> 620.82143
B14: 8 | C14: 1 | D14: =D13+C14 -> 5 | E14: =C14*'Cost Inputs'!$C$44 -> 1500 | F14: =D14*'Tier Pricing'!$E$23 -> 1268.6071 | G14: =E14+F14 -> 2768.6071 | H14: ='Cost Inputs'!$C$13+IF(D14>=10,'Cost Inputs'!$C$17,0)+IF(D14>=20,'Cost Inputs'!$C$18,0)+IF(D14>=30,'Cost Inputs'!$C$19,0)+IF(D14>=20,'Cost Inputs'!$C$20,0)+0+0 -> 902 | I14: =IF(D14<='Cost Inputs'!$C$28,D14*'Cost Inputs'!$C$26,D14*'Cost Inputs'!$C$27)+D14*'Tier Pricing'!$D$22*'Cost Inputs'!$C$40 -> 407 | J14: =H14+I14 -> 1309 | K14: =G14-J14 -> 1459.6071 | L14: =L13+K14 -> 2080.4286
B15: 9 | C15: 1 | D15: =D14+C15 -> 6 | E15: =C15*'Cost Inputs'!$C$44 -> 1500 | F15: =D15*'Tier Pricing'!$E$23 -> 1522.3286 | G15: =E15+F15 -> 3022.3286 | H15: ='Cost Inputs'!$C$13+IF(D15>=10,'Cost Inputs'!$C$17,0)+IF(D15>=20,'Cost Inputs'!$C$18,0)+IF(D15>=30,'Cost Inputs'!$C$19,0)+IF(D15>=20,'Cost Inputs'!$C$20,0)+0+0 -> 902 | I15: =IF(D15<='Cost Inputs'!$C$28,D15*'Cost Inputs'!$C$26,D15*'Cost Inputs'!$C$27)+D15*'Tier Pricing'!$D$22*'Cost Inputs'!$C$40 -> 488.4 | J15: =H15+I15 -> 1390.4 | K15: =G15-J15 -> 1631.9286 | L15: =L14+K15 -> 3712.3571
B16: 10 | C16: 2 | D16: =D15+C16 -> 8 | E16: =C16*'Cost Inputs'!$C$44 -> 3000 | F16: =D16*'Tier Pricing'!$E$23 -> 2029.7714 | G16: =E16+F16 -> 5029.7714 | H16: ='Cost Inputs'!$C$13+IF(D16>=10,'Cost Inputs'!$C$17,0)+IF(D16>=20,'Cost Inputs'!$C$18,0)+IF(D16>=30,'Cost Inputs'!$C$19,0)+IF(D16>=20,'Cost Inputs'!$C$20,0)+0+0 -> 902 | I16: =IF(D16<='Cost Inputs'!$C$28,D16*'Cost Inputs'!$C$26,D16*'Cost Inputs'!$C$27)+D16*'Tier Pricing'!$D$22*'Cost Inputs'!$C$40 -> 651.2 | J16: =H16+I16 -> 1553.2 | K16: =G16-J16 -> 3476.5714 | L16: =L15+K16 -> 7188.9286
B17: 11 | C17: 2 | D17: =D16+C17 -> 10 | E17: =C17*'Cost Inputs'!$C$44 -> 3000 | F17: =D17*'Tier Pricing'!$E$23 -> 2537.2143 | G17: =E17+F17 -> 5537.2143 | H17: ='Cost Inputs'!$C$13+IF(D17>=10,'Cost Inputs'!$C$17,0)+IF(D17>=20,'Cost Inputs'!$C$18,0)+IF(D17>=30,'Cost Inputs'!$C$19,0)+IF(D17>=20,'Cost Inputs'!$C$20,0)+0+0 -> 1022 | I17: =IF(D17<='Cost Inputs'!$C$28,D17*'Cost Inputs'!$C$26,D17*'Cost Inputs'!$C$27)+D17*'Tier Pricing'!$D$22*'Cost Inputs'!$C$40 -> 814 | J17: =H17+I17 -> 1836 | K17: =G17-J17 -> 3701.2143 | L17: =L16+K17 -> 10890.143
B18: 12 | C18: 2 | D18: =D17+C18 -> 12 | E18: =C18*'Cost Inputs'!$C$44 -> 3000 | F18: =D18*'Tier Pricing'!$E$23 -> 3044.6571 | G18: =E18+F18 -> 6044.6571 | H18: ='Cost Inputs'!$C$13+IF(D18>=10,'Cost Inputs'!$C$17,0)+IF(D18>=20,'Cost Inputs'!$C$18,0)+IF(D18>=30,'Cost Inputs'!$C$19,0)+IF(D18>=20,'Cost Inputs'!$C$20,0)+0+0 -> 1022 | I18: =IF(D18<='Cost Inputs'!$C$28,D18*'Cost Inputs'!$C$26,D18*'Cost Inputs'!$C$27)+D18*'Tier Pricing'!$D$22*'Cost Inputs'!$C$40 -> 976.8 | J18: =H18+I18 -> 1998.8 | K18: =G18-J18 -> 4045.8571 | L18: =L17+K18 -> 14936
B19: 13 | C19: 2 | D19: =D18+C19 -> 14 | E19: =C19*'Cost Inputs'!$C$44 -> 3000 | F19: =D19*'Tier Pricing'!$E$23 -> 3552.1 | G19: =E19+F19 -> 6552.1 | H19: ='Cost Inputs'!$C$13+IF(D19>=10,'Cost Inputs'!$C$17,0)+IF(D19>=20,'Cost Inputs'!$C$18,0)+IF(D19>=30,'Cost Inputs'!$C$19,0)+IF(D19>=20,'Cost Inputs'!$C$20,0)+0+0 -> 1022 | I19: =IF(D19<='Cost Inputs'!$C$28,D19*'Cost Inputs'!$C$26,D19*'Cost Inputs'!$C$27)+D19*'Tier Pricing'!$D$22*'Cost Inputs'!$C$40 -> 1139.6 | J19: =H19+I19 -> 2161.6 | K19: =G19-J19 -> 4390.5 | L19: =L18+K19 -> 19326.5
... B42: 36 | C42: 6 | D42: =D41+C42 -> 117 | E42: =C42*'Cost Inputs'!$C$44 -> 9000 | F42: =D42*'Tier Pricing'!$E$23 -> 29685.407 | G42: =E42+F42 -> 38685.407 | H42: ='Cost Inputs'!$C$13+IF(D42>=10,'Cost Inputs'!$C$17,0)+IF(D42>=20,'Cost Inputs'!$C$18,0)+IF(D42>=30,'Cost Inputs'!$C$19,0)+IF(D42>=20,'Cost Inputs'!$C$20,0)+0+0 -> 2622 | I42: =IF(D42<='Cost Inputs'!$C$28,D42*'Cost Inputs'!$C$26,D42*'Cost Inputs'!$C$27)+D42*'Tier Pricing'!$D$22*'Cost Inputs'!$C$40 -> 9523.8 | J42: =H42+I42 -> 12145.8 | K42: =G42-J42 -> 26539.607 | L42: =L41+K42 -> 355101.75
B43: 36-mo total | C43: =SUM(C7:C42) -> 117 | E43: =SUM(E7:E42) -> 175500 | F43: =SUM(F7:F42) -> 367642.35 | G43: =SUM(G7:G42) -> 543142.35 | H43: =SUM(H7:H42) -> 68442 | I43: =SUM(I7:I42) -> 119598.6 | J43: =SUM(J7:J42) -> 188040.6 | K43: =SUM(K7:K42) -> 355101.75 | L43: =L42 -> 355101.75

Sheet Profit Split
B2: Profit Split Scenarios
B3: Set each partner's percentage share. Profit from the Projection is allocated each month according to these splits. Negative profit (loss) is also shared — meaning each partner contributes that share of the subsidy.
B5: A · Equity split between partners
B6: Partner | C6: Equity % | D6: Role | F6: Notes
B7: Partner A (you) | C7: 0.5 | D7: Tech + product | F7: Adjust % if non-50/50 split agreed
B8: Partner B | C8: 0.5 | D8: Sales + hardware + ops | F8: Adjust % if non-50/50 split agreed
B9: Total | C9: =SUM(C7:C8) -> 1 | F9: Must equal 100%.
B11: B · Take-home per partner (from Projection sheet)
B12: Period | C12: Net profit (RM) | D12: Partner A (you) | E12: Partner B | F12: Notes
B13: Year 1 (months 1–12) | C13: =SUM(Projection!K7:K18) -> 14936 | D13: =C13*'Profit Split'!$C$7 -> 7468 | E13: =C13*'Profit Split'!$C$8 -> 7468 | F13: First full year of operation
B14: Year 2 (months 13–24) | C14: =SUM(Projection!K19:K30) -> 96344.929 | D14: =C14*'Profit Split'!$C$7 -> 48172.464 | E14: =C14*'Profit Split'!$C$8 -> 48172.464
B15: Year 3 (months 25–36) | C15: =SUM(Projection!K31:K42) -> 243820.82 | D15: =C15*'Profit Split'!$C$7 -> 121910.41 | E15: =C15*'Profit Split'!$C$8 -> 121910.41
B16: 36-month total | C16: =SUM(Projection!K7:K42) -> 355101.75 | D16: =C16*'Profit Split'!$C$7 -> 177550.88 | E16: =C16*'Profit Split'!$C$8 -> 177550.88 | F16: Total 3-year take-home per partner
B18: C · Subsidy budget tracking
B19: Subsidy cap (RM) — each partner agreed loss limit | C19: 8000 | F19: If cumulative cash drops below -2× this, reassess.
B20: Worst cumulative cash position (RM) | C20: =MIN(Projection!L8:L43) -> -1019.0357 | F20: The biggest hole you'll be in. Should be smaller than -2× subsidy cap.
B21: Worst position vs cap | C21: =IF(B20<-2*'Profit Split'!$C$19,"OVER BUDGET","OK") -> OK
